<?xml version="1.0" encoding="utf-8"?>
<!-- This URDF was automatically created by SolidWorks to URDF Exporter! Originally created by Stephen Brawner (brawner@gmail.com) 
     Commit Version: 1.6.0-4-g7f85cfe  Build Version: 1.6.7995.38578
     For more information, please see http://wiki.ros.org/sw_urdf_exporter -->
<robot
  name="graine_robot">
  <link
    name="base_link">
    <inertial>
      <origin
        xyz="0 -4.3368E-19 -0.025"
        rpy="0 0 0" />
      <mass
        value="0.56878" />
      <inertia
        ixx="0.00039528"
        ixy="-1.6544E-21"
        ixz="2.2581E-22"
        iyy="0.001191"
        iyz="-1.68E-21"
        izz="0.0013518" />
    </inertial>
    <visual>
      <origin
        xyz="0 0 0"
        rpy="0 0 0" />
      <geometry>
        <mesh
          filename="package://graine_robot/meshes/base_link.STL" />
      </geometry>
      <material
        name="">
        <color
          rgba="0.79216 0.81961 0.93333 1" />
      </material>
    </visual>
    <collision>
      <origin
        xyz="0 0 0"
        rpy="0 0 0" />
      <geometry>
        <mesh
          filename="package://graine_robot/meshes/base_link.STL" />
      </geometry>
    </collision>
  </link>
  <link
    name="wheel1_Link">
    <inertial>
      <origin
        xyz="0 -0.014932 -6.9389E-18"
        rpy="0 0 0" />
      <mass
        value="0.11467" />
      <inertia
        ixx="4.3926E-05"
        ixy="-1.1835E-37"
        ixz="-1.4583E-39"
        iyy="7.0705E-05"
        iyz="-4.4124E-23"
        izz="4.3926E-05" />
    </inertial>
    <visual>
      <origin
        xyz="0 0 0"
        rpy="0 0 0" />
      <geometry>
        <mesh
          filename="package://graine_robot/meshes/wheel1_Link.STL" />
      </geometry>
      <material
        name="">
        <color
          rgba="0.79216 0.81961 0.93333 1" />
      </material>
    </visual>
    <collision>
      <origin
        xyz="0 0 0"
        rpy="0 0 0" />
      <geometry>
        <mesh
          filename="package://graine_robot/meshes/wheel1_Link.STL" />
      </geometry>
    </collision>
  </link>
  <joint
    name="wheel1"
    type="continuous">
    <origin
      xyz="0.055 0.0775 -0.025"
      rpy="0 0 0" />
    <parent
      link="base_link" />
    <child
      link="wheel1_Link" />
    <axis
      xyz="0 1 0" />
  </joint>
  <link
    name="wheel2_Link">
    <inertial>
      <origin
        xyz="-1.3878E-17 -0.014932 -6.0715E-18"
        rpy="0 0 0" />
      <mass
        value="0.11467" />
      <inertia
        ixx="4.3926E-05"
        ixy="-1.1835E-37"
        ixz="-1.4583E-39"
        iyy="7.0705E-05"
        iyz="-4.4124E-23"
        izz="4.3926E-05" />
    </inertial>
    <visual>
      <origin
        xyz="0 0 0"
        rpy="0 0 0" />
      <geometry>
        <mesh
          filename="package://graine_robot/meshes/wheel2_Link.STL" />
      </geometry>
      <material
        name="">
        <color
          rgba="0.79216 0.81961 0.93333 1" />
      </material>
    </visual>
    <collision>
      <origin
        xyz="0 0 0"
        rpy="0 0 0" />
      <geometry>
        <mesh
          filename="package://graine_robot/meshes/wheel2_Link.STL" />
      </geometry>
    </collision>
  </link>
  <joint
    name="wheel2"
    type="continuous">
    <origin
      xyz="-0.055 0.0775 -0.025"
      rpy="0 0 0" />
    <parent
      link="base_link" />
    <child
      link="wheel2_Link" />
    <axis
      xyz="0 1 0" />
  </joint>
  <link
    name="wheel3_Link">
    <inertial>
      <origin
        xyz="-1.3878E-17 0.014932 -6.0715E-18"
        rpy="0 0 0" />
      <mass
        value="0.11467" />
      <inertia
        ixx="4.3926E-05"
        ixy="-1.1835E-37"
        ixz="1.4583E-39"
        iyy="7.0705E-05"
        iyz="4.4124E-23"
        izz="4.3926E-05" />
    </inertial>
    <visual>
      <origin
        xyz="0 0 0"
        rpy="0 0 0" />
      <geometry>
        <mesh
          filename="package://graine_robot/meshes/wheel3_Link.STL" />
      </geometry>
      <material
        name="">
        <color
          rgba="0.79216 0.81961 0.93333 1" />
      </material>
    </visual>
    <collision>
      <origin
        xyz="0 0 0"
        rpy="0 0 0" />
      <geometry>
        <mesh
          filename="package://graine_robot/meshes/wheel3_Link.STL" />
      </geometry>
    </collision>
  </link>
  <joint
    name="wheel3"
    type="continuous">
    <origin
      xyz="-0.055 -0.0775 -0.025"
      rpy="0 0 0" />
    <parent
      link="base_link" />
    <child
      link="wheel3_Link" />
    <axis
      xyz="0 1 0" />
  </joint>
  <link
    name="wheel4_Link">
    <inertial>
      <origin
        xyz="0 0 0"
        rpy="0 0 0" />
      <mass
        value="0" />
      <inertia
        ixx="0"
        ixy="0"
        ixz="0"
        iyy="0"
        iyz="0"
        izz="0" />
    </inertial>
    <visual>
      <origin
        xyz="0 0 0"
        rpy="0 0 0" />
      <geometry>
        <mesh
          filename="package://graine_robot/meshes/wheel4_Link.STL" />
      </geometry>
      <material
        name="">
        <color
          rgba="1 1 1 1" />
      </material>
    </visual>
    <collision>
      <origin
        xyz="0 0 0"
        rpy="0 0 0" />
      <geometry>
        <mesh
          filename="package://graine_robot/meshes/wheel4_Link.STL" />
      </geometry>
    </collision>
  </link>
  <joint
    name="wheel4"
    type="continuous">
    <origin
      xyz="0.055 -0.0775 -0.025"
      rpy="0 0 0" />
    <parent
      link="base_link" />
    <child
      link="wheel4_Link" />
    <axis
      xyz="0 1 0" />
  </joint>
</robot>