<?xml version="1.0" encoding="utf-8"?>
<!-- This URDF was automatically created by SolidWorks to URDF Exporter! Originally created by Stephen Brawner (brawner@gmail.com) 
     Commit Version: 1.6.0-4-g7f85cfe  Build Version: 1.6.7995.38578
     For more information, please see http://wiki.ros.org/sw_urdf_exporter -->
<robot
  name="CleaningBoat">
  <link
    name="base_boat">
    <inertial>
      <origin
        xyz="-0.0504299123892678 -0.00399328466998017 -0.174875808375425"
        rpy="0 0 0" />
      <mass
        value="13.4637284801427" />
      <inertia
        ixx="0.12480067925069"
        ixy="1.14626035110482E-06"
        ixz="-0.00148139606626633"
        iyy="0.0960555455042695"
        iyz="9.16339224172531E-06"
        izz="0.136334518910552" />
    </inertial>
    <visual>
      <origin
        xyz="0 0 0"
        rpy="0 0 0" />
      <geometry>
        <mesh
          filename="package://CleaningBoat/meshes/base_boat.STL" />
      </geometry>
      <material
        name="">
        <color
          rgba="0.752941176470588 0.752941176470588 0.752941176470588 1" />
      </material>
    </visual>
    <collision>
      <origin
        xyz="0 0 0"
        rpy="0 0 0" />
      <geometry>
        <mesh
          filename="package://CleaningBoat/meshes/base_boat.STL" />
      </geometry>
    </collision>
  </link>
  <link
    name="axe_droit">
    <inertial>
      <origin
        xyz="0.0230109768079529 -1.26854790101494E-06 4.87990531770899E-06"
        rpy="0 0 0" />
      <mass
        value="0.0681006952021269" />
      <inertia
        ixx="1.72388165413107E-05"
        ixy="1.96746157954376E-09"
        ixz="-7.48619976047338E-09"
        iyy="2.32241540649935E-05"
        iyz="-1.63733967087246E-09"
        izz="2.32478078421983E-05" />
    </inertial>
    <visual>
      <origin
        xyz="0 0 0"
        rpy="0 0 0" />
      <geometry>
        <mesh
          filename="package://CleaningBoat/meshes/axe_droit.STL" />
      </geometry>
      <material
        name="">
        <color
          rgba="1 1 1 1" />
      </material>
    </visual>
    <collision>
      <origin
        xyz="0 0 0"
        rpy="0 0 0" />
      <geometry>
        <mesh
          filename="package://CleaningBoat/meshes/axe_droit.STL" />
      </geometry>
    </collision>
  </link>
  <joint
    name="axe_droit_joint"
    type="fixed">
    <origin
      xyz="-0.30981 -0.40127 -0.3785"
      rpy="0 0 0" />
    <parent
      link="base_boat" />
    <child
      link="axe_droit" />
    <axis
      xyz="0 0 0" />
  </joint>
  <link
    name="fan_droite">
    <inertial>
      <origin
        xyz="0.012188 -1.9617E-09 4.458E-08"
        rpy="0 0 0" />
      <mass
        value="0.0079579" />
      <inertia
        ixx="3.7271E-06"
        ixy="2.1297E-13"
        ixz="-8.3402E-13"
        iyy="2.3933E-06"
        iyz="-4.6164E-10"
        izz="2.3945E-06" />
    </inertial>
    <visual>
      <origin
        xyz="0 0 0"
        rpy="0 0 0" />
      <geometry>
        <mesh
          filename="package://CleaningBoat/meshes/fan_droite.STL" />
      </geometry>
      <material
        name="">
        <color
          rgba="0.79216 0.81961 0.93333 1" />
      </material>
    </visual>
    <collision>
      <origin
        xyz="0 0 0"
        rpy="0 0 0" />
      <geometry>
        <mesh
          filename="package://CleaningBoat/meshes/fan_droite.STL" />
      </geometry>
    </collision>
  </link>
  <joint
    name="fan_droite_join"
    type="continuous">
    <origin
      xyz="0 0 0"
      rpy="0 0 0" />
    <parent
      link="axe_droit" />
    <child
      link="fan_droite" />
    <axis
      xyz="1 0 0" />
  </joint>
  <link
    name="axe_gauche">
    <inertial>
      <origin
        xyz="0 0 0"
        rpy="0 0 0" />
      <mass
        value="0" />
      <inertia
        ixx="0"
        ixy="0"
        ixz="0"
        iyy="0"
        iyz="0"
        izz="0" />
    </inertial>
    <visual>
      <origin
        xyz="0 0 0"
        rpy="0 0 0" />
      <geometry>
        <mesh
          filename="package://CleaningBoat/meshes/axe_gauche.STL" />
      </geometry>
      <material
        name="">
        <color
          rgba="1 1 1 1" />
      </material>
    </visual>
    <collision>
      <origin
        xyz="0 0 0"
        rpy="0 0 0" />
      <geometry>
        <mesh
          filename="package://CleaningBoat/meshes/axe_gauche.STL" />
      </geometry>
    </collision>
  </link>
  <joint
    name="axe_gauche_joint"
    type="fixed">
    <origin
      xyz="-0.31334 0.39873 -0.3785"
      rpy="0 0 0" />
    <parent
      link="base_boat" />
    <child
      link="axe_gauche" />
    <axis
      xyz="0 0 0" />
  </joint>
  <link
    name="fan_gauche">
    <inertial>
      <origin
        xyz="0.015709 -1.9617E-09 4.458E-08"
        rpy="0 0 0" />
      <mass
        value="0.0079579" />
      <inertia
        ixx="3.7271E-06"
        ixy="2.1297E-13"
        ixz="-8.3402E-13"
        iyy="2.3933E-06"
        iyz="-4.6164E-10"
        izz="2.3945E-06" />
    </inertial>
    <visual>
      <origin
        xyz="0 0 0"
        rpy="0 0 0" />
      <geometry>
        <mesh
          filename="package://CleaningBoat/meshes/fan_gauche.STL" />
      </geometry>
      <material
        name="">
        <color
          rgba="0.79216 0.81961 0.93333 1" />
      </material>
    </visual>
    <collision>
      <origin
        xyz="0 0 0"
        rpy="0 0 0" />
      <geometry>
        <mesh
          filename="package://CleaningBoat/meshes/fan_gauche.STL" />
      </geometry>
    </collision>
  </link>
  <joint
    name="fan_gauche_joint"
    type="continuous">
    <origin
      xyz="0 0 0"
      rpy="0 0 0" />
    <parent
      link="axe_gauche" />
    <child
      link="fan_gauche" />
    <axis
      xyz="1 0 0" />
  </joint>
</robot>