<?xml version="1.0" encoding="utf-8"?>
<!-- This URDF was automatically created by SolidWorks to URDF Exporter! Originally created by Stephen Brawner (brawner@gmail.com) 
     Commit Version: 1.6.0-4-g7f85cfe  Build Version: 1.6.7995.38578
     For more information, please see http://wiki.ros.org/sw_urdf_exporter -->
<robot
  name="boatcleaningd">
  <link
    name="baseboatclening">
    <inertial>
      <origin
        xyz="-0.052968 7.6111E-07 0.24766"
        rpy="0 0 0" />
      <mass
        value="13.599" />
      <inertia
        ixx="0.125"
        ixy="9.4664E-07"
        ixz="-0.0014834"
        iyy="0.096195"
        iyz="8.2617E-06"
        izz="0.13644" />
    </inertial>
    <visual>
      <origin
        xyz="0 0 0"
        rpy="0 0 0" />
      <geometry>
        <mesh
          filename="package://boatcleaningd/meshes/baseboatclening.STL" />
      </geometry>
      <material
        name="">
        <color
          rgba="1 1 1 1" />
      </material>
    </visual>
    <collision>
      <origin
        xyz="0 0 0"
        rpy="0 0 0" />
      <geometry>
        <mesh
          filename="package://boatcleaningd/meshes/baseboatclening.STL" />
      </geometry>
    </collision>
  </link>
  <link
    name="axegauche">
    <inertial>
      <origin
        xyz="1.27980339592604E-06 -4.87536581963988E-06 0.0164902227581927"
        rpy="0 0 0" />
      <mass
        value="0.0667653794483585" />
      <inertia
        ixx="2.27687803802025E-05"
        ixy="-1.64257271106359E-09"
        ixz="-1.94711082041723E-09"
        iyy="2.27919562045217E-05"
        iyz="7.33475975049114E-09"
        izz="1.69007967588849E-05" />
    </inertial>
    <visual>
      <origin
        xyz="0 0 0"
        rpy="0 0 0" />
      <geometry>
        <mesh
          filename="package://boatcleaningd/meshes/axegauche.STL" />
      </geometry>
      <material
        name="">
        <color
          rgba="0.792156862745098 0.819607843137255 0.933333333333333 1" />
      </material>
    </visual>
    <collision>
      <origin
        xyz="0 0 0"
        rpy="0 0 0" />
      <geometry>
        <mesh
          filename="package://boatcleaningd/meshes/axegauche.STL" />
      </geometry>
    </collision>
  </link>
  <joint
    name="axegauchejoint"
    type="fixed">
    <origin
      xyz="-0.30329 0.39873 0.046"
      rpy="-1.5708 -0.0017453 -1.5708" />
    <parent
      link="baseboatclening" />
    <child
      link="axegauche" />
    <axis
      xyz="0 0 0" />
  </joint>
  <link
    name="fangauche">
    <inertial>
      <origin
        xyz="0.0121880649596038 -1.96166327626202E-09 4.4580179797693E-08"
        rpy="0 0 0" />
      <mass
        value="0.00795785659641876" />
      <inertia
        ixx="3.72710558894515E-06"
        ixy="2.12970221795389E-13"
        ixz="-8.34019277804446E-13"
        iyy="2.39331655167285E-06"
        iyz="-4.61638273468624E-10"
        izz="2.39447831194742E-06" />
    </inertial>
    <visual>
      <origin
        xyz="0 0 0"
        rpy="0 0 0" />
      <geometry>
        <mesh
          filename="package://boatcleaningd/meshes/fangauche.STL" />
      </geometry>
      <material
        name="">
        <color
          rgba="0.792156862745098 0.819607843137255 0.933333333333333 1" />
      </material>
    </visual>
    <collision>
      <origin
        xyz="0 0 0"
        rpy="0 0 0" />
      <geometry>
        <mesh
          filename="package://boatcleaningd/meshes/fangauche.STL" />
      </geometry>
    </collision>
  </link>
  <joint
    name="fangauchejoint"
    type="continuous">
    <origin
      xyz="0 0 -0.0065208"
      rpy="1.5691 -1.5708 0" />
    <parent
      link="axegauche" />
    <child
      link="fangauche" />
    <axis
      xyz="1 0 0" />
  </joint>
  <link
    name="axedroit">
    <inertial>
      <origin
        xyz="1.27706300609431E-06 -4.87768385248888E-06 0.0164902268079528"
        rpy="0 0 0" />
      <mass
        value="0.0667653874530656" />
      <inertia
        ixx="2.27687841690494E-05"
        ixy="-1.64569925594943E-09"
        ixz="-1.94169064678966E-09"
        iyy="2.2791962798787E-05"
        iyz="7.33603381553864E-09"
        izz="1.6900800530698E-05" />
    </inertial>
    <visual>
      <origin
        xyz="0 0 0"
        rpy="0 0 0" />
      <geometry>
        <mesh
          filename="package://boatcleaningd/meshes/axedroit.STL" />
      </geometry>
      <material
        name="">
        <color
          rgba="0.792156862745098 0.819607843137255 0.933333333333333 1" />
      </material>
    </visual>
    <collision>
      <origin
        xyz="0 0 0"
        rpy="0 0 0" />
      <geometry>
        <mesh
          filename="package://boatcleaningd/meshes/axedroit.STL" />
      </geometry>
    </collision>
  </link>
  <joint
    name="axedroitjoint"
    type="fixed">
    <origin
      xyz="-0.30329 -0.40127 0.046"
      rpy="-1.5708 -0.0017453 -1.5708" />
    <parent
      link="baseboatclening" />
    <child
      link="axedroit" />
    <axis
      xyz="0 0 0" />
  </joint>
  <link
    name="fandroit">
    <inertial>
      <origin
        xyz="0.0111720649596023 -1.96166084764915E-09 4.45801802001489E-08"
        rpy="0 0 0" />
      <mass
        value="0.0079578565964185" />
      <inertia
        ixx="3.72710558894501E-06"
        ixy="2.12970222260678E-13"
        ixz="-8.34019270406672E-13"
        iyy="2.39331655167276E-06"
        iyz="-4.6163827347066E-10"
        izz="2.39447831194737E-06" />
    </inertial>
    <visual>
      <origin
        xyz="0 0 0"
        rpy="0 0 0" />
      <geometry>
        <mesh
          filename="package://boatcleaningd/meshes/fandroit.STL" />
      </geometry>
      <material
        name="">
        <color
          rgba="0.792156862745098 0.819607843137255 0.933333333333333 1" />
      </material>
    </visual>
    <collision>
      <origin
        xyz="0 0 0"
        rpy="0 0 0" />
      <geometry>
        <mesh
          filename="package://boatcleaningd/meshes/fandroit.STL" />
      </geometry>
    </collision>
  </link>
  <joint
    name="fandroitjoint"
    type="continuous">
    <origin
      xyz="0 0 -0.0055047"
      rpy="1.5691 -1.5708 0" />
    <parent
      link="axedroit" />
    <child
      link="fandroit" />
    <axis
      xyz="1 0 0" />
  </joint>
</robot>