<?xml version="1.0" encoding="utf-8"?>
<!-- This URDF was automatically created by SolidWorks to URDF Exporter! Originally created by Stephen Brawner (brawner@gmail.com) 
     Commit Version: 1.6.0-4-g7f85cfe  Build Version: 1.6.7995.38578
     For more information, please see http://wiki.ros.org/sw_urdf_exporter -->
<robot
  name="dronesmb">
  <link
    name="base_drone">
    <inertial>
      <origin
        xyz="0.0044251 0.030145 0.182"
        rpy="0 0 0" />
      <mass
        value="0.77242" />
      <inertia
        ixx="0.00057079"
        ixy="1.0111E-11"
        ixz="-1.9621E-10"
        iyy="0.00086065"
        iyz="-1.6818E-11"
        izz="0.00059684" />
    </inertial>
    <visual>
      <origin
        xyz="0 0 0"
        rpy="0 0 0" />
      <geometry>
        <mesh
          filename="package://dronesmb/meshes/base_drone.STL" />
      </geometry>
      <material
        name="">
        <color
          rgba="0.50196 0.50196 0.50196 1" />
      </material>
    </visual>
    <collision>
      <origin
        xyz="0 0 0"
        rpy="0 0 0" />
      <geometry>
        <mesh
          filename="package://dronesmb/meshes/base_drone.STL" />
      </geometry>
    </collision>
  </link>
  <link
    name="fan_AVD">
    <inertial>
      <origin
        xyz="-1.1818E-10 4.7891E-10 -0.0022673"
        rpy="0 0 0" />
      <mass
        value="0.079235" />
      <inertia
        ixx="0.00056544"
        ixy="3.5825E-05"
        ixz="2.2128E-14"
        iyy="4.6143E-06"
        iyz="-9.0619E-14"
        izz="0.00056968" />
    </inertial>
    <visual>
      <origin
        xyz="0 0 0"
        rpy="0 0 0" />
      <geometry>
        <mesh
          filename="package://dronesmb/meshes/fan_AVD.STL" />
      </geometry>
      <material
        name="">
        <color
          rgba="0.59216 0.66667 0.68235 1" />
      </material>
    </visual>
    <collision>
      <origin
        xyz="0 0 0"
        rpy="0 0 0" />
      <geometry>
        <mesh
          filename="package://dronesmb/meshes/fan_AVD.STL" />
      </geometry>
    </collision>
  </link>
  <joint
    name="fan_AVDjoint"
    type="continuous">
    <origin
      xyz="0.16741 -0.34499 0.072835"
      rpy="0 0 0" />
    <parent
      link="base_drone" />
    <child
      link="fan_AVD" />
    <axis
      xyz="0 0 1" />
  </joint>
  <link
    name="fan_AVG">
    <inertial>
      <origin
        xyz="7.7592E-10 3.1356E-11 -0.0022673"
        rpy="0 0 0" />
      <mass
        value="0.079235" />
      <inertia
        ixx="0.00053874"
        ixy="0.0001247"
        ixz="6.9632E-14"
        iyy="3.1323E-05"
        iyz="2.4299E-13"
        izz="0.00056968" />
    </inertial>
    <visual>
      <origin
        xyz="0 0 0"
        rpy="0 0 0" />
      <geometry>
        <mesh
          filename="package://dronesmb/meshes/fan_AVG.STL" />
      </geometry>
      <material
        name="">
        <color
          rgba="0.59216 0.66667 0.68235 1" />
      </material>
    </visual>
    <collision>
      <origin
        xyz="0 0 0"
        rpy="0 0 0" />
      <geometry>
        <mesh
          filename="package://dronesmb/meshes/fan_AVG.STL" />
      </geometry>
    </collision>
  </link>
  <joint
    name="fan_AVGjoint"
    type="continuous">
    <origin
      xyz="0.16741 -0.019012 0.072835"
      rpy="0 0 0" />
    <parent
      link="base_drone" />
    <child
      link="fan_AVG" />
    <axis
      xyz="0 0 1" />
  </joint>
  <link
    name="fan_AD">
    <inertial>
      <origin
        xyz="-4.9041E-10 5.3118E-11 -0.0022673"
        rpy="0 0 0" />
      <mass
        value="0.079235" />
      <inertia
        ixx="4.7424E-05"
        ixy="0.00015317"
        ixz="9.2715E-14"
        iyy="0.00052263"
        iyz="-1.027E-14"
        izz="0.00056968" />
    </inertial>
    <visual>
      <origin
        xyz="0 0 0"
        rpy="0 0 0" />
      <geometry>
        <mesh
          filename="package://dronesmb/meshes/fan_AD.STL" />
      </geometry>
      <material
        name="">
        <color
          rgba="0.59216 0.66667 0.68235 1" />
      </material>
    </visual>
    <collision>
      <origin
        xyz="0 0 0"
        rpy="0 0 0" />
      <geometry>
        <mesh
          filename="package://dronesmb/meshes/fan_AD.STL" />
      </geometry>
    </collision>
  </link>
  <joint
    name="fan_ADjoint"
    type="continuous">
    <origin
      xyz="-0.15856 -0.34499 0.072835"
      rpy="0 0 0" />
    <parent
      link="base_drone" />
    <child
      link="fan_AD" />
    <axis
      xyz="0 0 1" />
  </joint>
  <link
    name="fan_AG">
    <inertial>
      <origin
        xyz="0 0 0"
        rpy="0 0 0" />
      <mass
        value="0" />
      <inertia
        ixx="0"
        ixy="0"
        ixz="0"
        iyy="0"
        iyz="0"
        izz="0" />
    </inertial>
    <visual>
      <origin
        xyz="0 0 0"
        rpy="0 0 0" />
      <geometry>
        <mesh
          filename="package://dronesmb/meshes/fan_AG.STL" />
      </geometry>
      <material
        name="">
        <color
          rgba="1 1 1 1" />
      </material>
    </visual>
    <collision>
      <origin
        xyz="0 0 0"
        rpy="0 0 0" />
      <geometry>
        <mesh
          filename="package://dronesmb/meshes/fan_AG.STL" />
      </geometry>
    </collision>
  </link>
  <joint
    name="fan_AGjoint"
    type="continuous">
    <origin
      xyz="-0.15856 -0.019012 0.072835"
      rpy="0 0 0" />
    <parent
      link="base_drone" />
    <child
      link="fan_AG" />
    <axis
      xyz="0 0 1" />
  </joint>
</robot>