<?xml version="1.0" encoding="utf-8"?>
<!-- This URDF was automatically created by SolidWorks to URDF Exporter! Originally created by Stephen Brawner (brawner@gmail.com) 
     Commit Version: 1.6.0-4-g7f85cfe  Build Version: 1.6.7995.38578
     For more information, please see http://wiki.ros.org/sw_urdf_exporter -->
<robot
  name="dronesma">
  <link
    name="base_drone">
    <inertial>
      <origin
        xyz="0 0 0"
        rpy="0 0 0" />
      <mass
        value="0.77242" />
      <inertia
        ixx="0.00057079"
        ixy="1.9621E-10"
        ixz="1.0111E-11"
        iyy="0.00059684"
        iyz="1.6818E-11"
        izz="0.00086065" />
    </inertial>
    <visual>
      <origin
        xyz="0 0 0"
        rpy="0 0 0" />
      <geometry>
        <mesh
          filename="package://dronesma/meshes/base_drone.STL" />
      </geometry>
      <material
        name="">
        <color
          rgba="0.50196 0.50196 0.50196 1" />
      </material>
    </visual>
    <collision>
      <origin
        xyz="0 0 0"
        rpy="0 0 0" />
      <geometry>
        <mesh
          filename="package://dronesma/meshes/base_drone.STL" />
      </geometry>
    </collision>
  </link>
  <link
    name="fan_AVD">
    <inertial>
      <origin
        xyz="-1.1724E-10 4.7289E-10 -0.0022673"
        rpy="0 0 0" />
      <mass
        value="0.079235" />
      <inertia
        ixx="0.00056544"
        ixy="3.5825E-05"
        ixz="2.1611E-14"
        iyy="4.6143E-06"
        iyz="-8.9423E-14"
        izz="0.00056968" />
    </inertial>
    <visual>
      <origin
        xyz="0 0 0"
        rpy="0 0 0" />
      <geometry>
        <mesh
          filename="package://dronesma/meshes/fan_AVD.STL" />
      </geometry>
      <material
        name="">
        <color
          rgba="0.59216 0.66667 0.68235 1" />
      </material>
    </visual>
    <collision>
      <origin
        xyz="0 0 0"
        rpy="0 0 0" />
      <geometry>
        <mesh
          filename="package://dronesma/meshes/fan_AVD.STL" />
      </geometry>
    </collision>
  </link>
  <joint
    name="fan_AVDjoint"
    type="continuous">
    <origin
      xyz="0.16299 -0.16299 0.2345"
      rpy="0 0 0" />
    <parent
      link="base_drone" />
    <child
      link="fan_AVD" />
    <axis
      xyz="0 0 -1" />
  </joint>
  <link
    name="fan_AVG">
    <inertial>
      <origin
        xyz="7.7389E-10 3.7683E-11 -0.0022673"
        rpy="0 0 0" />
      <mass
        value="0.079235" />
      <inertia
        ixx="0.00053874"
        ixy="0.0001247"
        ixz="6.9877E-14"
        iyy="3.1323E-05"
        iyz="2.427E-13"
        izz="0.00056968" />
    </inertial>
    <visual>
      <origin
        xyz="0 0 0"
        rpy="0 0 0" />
      <geometry>
        <mesh
          filename="package://dronesma/meshes/fan_AVG.STL" />
      </geometry>
      <material
        name="">
        <color
          rgba="0.59216 0.66667 0.68235 1" />
      </material>
    </visual>
    <collision>
      <origin
        xyz="0 0 0"
        rpy="0 0 0" />
      <geometry>
        <mesh
          filename="package://dronesma/meshes/fan_AVG.STL" />
      </geometry>
    </collision>
  </link>
  <joint
    name="fan_AVGjoint"
    type="continuous">
    <origin
      xyz="0.16299 0.16299 0.2345"
      rpy="0 0 0" />
    <parent
      link="base_drone" />
    <child
      link="fan_AVG" />
    <axis
      xyz="0 0 -1" />
  </joint>
  <link
    name="fan_AD">
    <inertial>
      <origin
        xyz="-4.8444E-10 5.1936E-11 -0.0022673"
        rpy="0 0 0" />
      <mass
        value="0.079235" />
      <inertia
        ixx="4.7424E-05"
        ixy="0.00015317"
        ixz="9.1414E-14"
        iyy="0.00052263"
        iyz="-1.0346E-14"
        izz="0.00056968" />
    </inertial>
    <visual>
      <origin
        xyz="0 0 0"
        rpy="0 0 0" />
      <geometry>
        <mesh
          filename="package://dronesma/meshes/fan_AD.STL" />
      </geometry>
      <material
        name="">
        <color
          rgba="0.59216 0.66667 0.68235 1" />
      </material>
    </visual>
    <collision>
      <origin
        xyz="0 0 0"
        rpy="0 0 0" />
      <geometry>
        <mesh
          filename="package://dronesma/meshes/fan_AD.STL" />
      </geometry>
    </collision>
  </link>
  <joint
    name="fan_ADjoint"
    type="continuous">
    <origin
      xyz="-0.16299 -0.16299 0.2345"
      rpy="0 0 0" />
    <parent
      link="base_drone" />
    <child
      link="fan_AD" />
    <axis
      xyz="0 0 -1" />
  </joint>
  <link
    name="fan_AG">
    <inertial>
      <origin
        xyz="-2.8687E-10 3.938E-10 -0.0022673"
        rpy="0 0 0" />
      <mass
        value="0.079235" />
      <inertia
        ixx="0.00046072"
        ixy="0.00022147"
        ixz="5.3729E-14"
        iyy="0.00010934"
        iyz="-7.4677E-14"
        izz="0.00056968" />
    </inertial>
    <visual>
      <origin
        xyz="0 0 0"
        rpy="0 0 0" />
      <geometry>
        <mesh
          filename="package://dronesma/meshes/fan_AG.STL" />
      </geometry>
      <material
        name="">
        <color
          rgba="0.59216 0.66667 0.68235 1" />
      </material>
    </visual>
    <collision>
      <origin
        xyz="0 0 0"
        rpy="0 0 0" />
      <geometry>
        <mesh
          filename="package://dronesma/meshes/fan_AG.STL" />
      </geometry>
    </collision>
  </link>
  <joint
    name="fan_AGjoint"
    type="continuous">
    <origin
      xyz="-0.16299 0.16299 0.2345"
      rpy="0 0 0" />
    <parent
      link="base_drone" />
    <child
      link="fan_AG" />
    <axis
      xyz="0 0 -1" />
  </joint>
</robot>