<?xml version="1.0" encoding="utf-8"?>
<!-- This URDF was automatically created by SolidWorks to URDF Exporter! Originally created by Stephen Brawner (brawner@gmail.com) 
     Commit Version: 1.6.0-4-g7f85cfe  Build Version: 1.6.7995.38578
     For more information, please see http://wiki.ros.org/sw_urdf_exporter -->
<robot
  name="boatcleaningc">
  <link
    name="baseboatclening">
    <inertial>
      <origin
        xyz="-0.0129680077841765 1.25727561811617E-06 -0.0543415157249071"
        rpy="0 0 0" />
      <mass
        value="13.5985858196954" />
      <inertia
        ixx="0.12499527878428"
        ixy="8.1696015611578E-07"
        ixz="-0.00148374605527537"
        iyy="0.0961950105001574"
        iyz="8.27994826632574E-06"
        izz="0.136442575579436" />
    </inertial>
    <visual>
      <origin
        xyz="0 0 0"
        rpy="0 0 0" />
      <geometry>
        <mesh
          filename="package://boatcleaningc/meshes/baseboatclening.STL" />
      </geometry>
      <material
        name="">
        <color
          rgba="1 1 1 1" />
      </material>
    </visual>
    <collision>
      <origin
        xyz="0 0 0"
        rpy="0 0 0" />
      <geometry>
        <mesh
          filename="package://boatcleaningc/meshes/baseboatclening.STL" />
      </geometry>
    </collision>
  </link>
  <link
    name="axegauche">
    <inertial>
      <origin
        xyz="1.27679435346639E-06 -4.87775281632352E-06 0.0164902272597591"
        rpy="0 0 0" />
      <mass
        value="0.0667653906372772" />
      <inertia
        ixx="2.27687846986066E-05"
        ixy="-1.64564197087163E-09"
        ixz="-1.94145680803022E-09"
        iyy="2.27919636489373E-05"
        iyz="7.33602396572131E-09"
        izz="1.69008013245686E-05" />
    </inertial>
    <visual>
      <origin
        xyz="0 0 0"
        rpy="0 0 0" />
      <geometry>
        <mesh
          filename="package://boatcleaningc/meshes/axegauche.STL" />
      </geometry>
      <material
        name="">
        <color
          rgba="0.792156862745098 0.819607843137255 0.933333333333333 1" />
      </material>
    </visual>
    <collision>
      <origin
        xyz="0 0 0"
        rpy="0 0 0" />
      <geometry>
        <mesh
          filename="package://boatcleaningc/meshes/axegauche.STL" />
      </geometry>
    </collision>
  </link>
  <joint
    name="axegauchejoint"
    type="fixed">
    <origin
      xyz="-0.263293964432029 0.398727536440511 -0.255999999999994"
      rpy="-1.5707963267949 -0.0017453292519949 -1.5707963267949" />
    <parent
      link="baseboatclening" />
    <child
      link="axegauche" />
    <axis
      xyz="0 0 0" />
  </joint>
  <link
    name="fangauche">
    <inertial>
      <origin
        xyz="0.0121880649596051 -1.96166660693109E-09 4.45801809634272E-08"
        rpy="0 0 0" />
      <mass
        value="0.00795785659641826" />
      <inertia
        ixx="3.72710558894489E-06"
        ixy="2.12970220347823E-13"
        ixz="-8.34019260089533E-13"
        iyy="2.39331655167268E-06"
        iyz="-4.61638273535348E-10"
        izz="2.39447831194732E-06" />
    </inertial>
    <visual>
      <origin
        xyz="0 0 0"
        rpy="0 0 0" />
      <geometry>
        <mesh
          filename="package://boatcleaningc/meshes/fangauche.STL" />
      </geometry>
      <material
        name="">
        <color
          rgba="0.792156862745098 0.819607843137255 0.933333333333333 1" />
      </material>
    </visual>
    <collision>
      <origin
        xyz="0 0 0"
        rpy="0 0 0" />
      <geometry>
        <mesh
          filename="package://boatcleaningc/meshes/fangauche.STL" />
      </geometry>
    </collision>
  </link>
  <joint
    name="fangauchejoint"
    type="continuous">
    <origin
      xyz="0 0 -0.0065208"
      rpy="1.5691 -1.5708 0" />
    <parent
      link="axegauche" />
    <child
      link="fangauche" />
    <axis
      xyz="1 0 0" />
  </joint>
  <link
    name="axedroit">
    <inertial>
      <origin
        xyz="1.27706300609431E-06 -4.87768385248888E-06 0.0164902268079528"
        rpy="0 0 0" />
      <mass
        value="0.0667653874530656" />
      <inertia
        ixx="2.2768784169048E-05"
        ixy="-1.64569925595665E-09"
        ixz="-1.94169064678752E-09"
        iyy="2.27919627987871E-05"
        iyz="7.33603381553706E-09"
        izz="1.69008005306967E-05" />
    </inertial>
    <visual>
      <origin
        xyz="0 0 0"
        rpy="0 0 0" />
      <geometry>
        <mesh
          filename="package://boatcleaningc/meshes/axedroit.STL" />
      </geometry>
      <material
        name="">
        <color
          rgba="0.792156862745098 0.819607843137255 0.933333333333333 1" />
      </material>
    </visual>
    <collision>
      <origin
        xyz="0 0 0"
        rpy="0 0 0" />
      <geometry>
        <mesh
          filename="package://boatcleaningc/meshes/axedroit.STL" />
      </geometry>
    </collision>
  </link>
  <joint
    name="axedroitjoint"
    type="fixed">
    <origin
      xyz="-0.263293964432035 -0.401272463559541 -0.255999999999994"
      rpy="-1.5707963267949 -0.00174532925200045 -1.5707963267949" />
    <parent
      link="baseboatclening" />
    <child
      link="axedroit" />
    <axis
      xyz="0 0 0" />
  </joint>
  <link
    name="fandroit">
    <inertial>
      <origin
        xyz="0.0111720649596025 -1.96166084764915E-09 4.45801802140267E-08"
        rpy="0 0 0" />
      <mass
        value="0.0079578565964185" />
      <inertia
        ixx="3.72710558894501E-06"
        ixy="2.12970222312377E-13"
        ixz="-8.34019270254807E-13"
        iyy="2.39331655167276E-06"
        iyz="-4.61638273470614E-10"
        izz="2.39447831194736E-06" />
    </inertial>
    <visual>
      <origin
        xyz="0 0 0"
        rpy="0 0 0" />
      <geometry>
        <mesh
          filename="package://boatcleaningc/meshes/fandroit.STL" />
      </geometry>
      <material
        name="">
        <color
          rgba="0.792156862745098 0.819607843137255 0.933333333333333 1" />
      </material>
    </visual>
    <collision>
      <origin
        xyz="0 0 0"
        rpy="0 0 0" />
      <geometry>
        <mesh
          filename="package://boatcleaningc/meshes/fandroit.STL" />
      </geometry>
    </collision>
  </link>
  <joint
    name="fandroitjoint"
    type="continuous">
    <origin
      xyz="0 0 -0.0055047"
      rpy="1.5691 -1.5708 0" />
    <parent
      link="axedroit" />
    <child
      link="fandroit" />
    <axis
      xyz="1 0 0" />
  </joint>
</robot>