<?xml version="1.0" encoding="utf-8"?>
<!-- This URDF was automatically created by SolidWorks to URDF Exporter! Originally created by Stephen Brawner (brawner@gmail.com) 
     Commit Version: 1.6.0-4-g7f85cfe  Build Version: 1.6.7995.38578
     For more information, please see http://wiki.ros.org/sw_urdf_exporter -->
<robot
  name="grobot">
  <link
    name="base_link">
    <inertial>
      <origin
        xyz="0.00093678 0.00060805 -0.043"
        rpy="0 0 0" />
      <mass
        value="0.44251" />
      <inertia
        ixx="0.0009344"
        ixy="5.78E-09"
        ixz="1.8097E-19"
        iyy="0.0017285"
        iyz="1.244E-06"
        izz="0.0024323" />
    </inertial>
    <visual>
      <origin
        xyz="0 0 0"
        rpy="0 0 0" />
      <geometry>
        <mesh
          filename="package://grobot/meshes/base_link.STL" />
      </geometry>
      <material
        name="">
        <color
          rgba="0.79216 0.81961 0.93333 1" />
      </material>
    </visual>
    <collision>
      <origin
        xyz="0 0 0"
        rpy="0 0 0" />
      <geometry>
        <mesh
          filename="package://grobot/meshes/base_link.STL" />
      </geometry>
    </collision>
  </link>
  <link
    name="axe2_Link">
    <inertial>
      <origin
        xyz="-1.3878E-17 5.8981E-17 -5.5511E-17"
        rpy="0 0 0" />
      <mass
        value="0.024347" />
      <inertia
        ixx="0.00019513"
        ixy="7.5161E-21"
        ixz="2.2403E-25"
        iyy="3.0434E-07"
        iyz="3.7028E-20"
        izz="0.00019513" />
    </inertial>
    <visual>
      <origin
        xyz="0 0 0"
        rpy="0 0 0" />
      <geometry>
        <mesh
          filename="package://grobot/meshes/axe2_Link.STL" />
      </geometry>
      <material
        name="">
        <color
          rgba="0.79216 0.81961 0.93333 1" />
      </material>
    </visual>
    <collision>
      <origin
        xyz="0 0 0"
        rpy="0 0 0" />
      <geometry>
        <mesh
          filename="package://grobot/meshes/axe2_Link.STL" />
      </geometry>
    </collision>
  </link>
  <joint
    name="axe2_joint"
    type="fixed">
    <origin
      xyz="0.085583 -0.00088809 -0.043"
      rpy="0 0 0" />
    <parent
      link="base_link" />
    <child
      link="axe2_Link" />
    <axis
      xyz="0 0 0" />
  </joint>
  <link
    name="wheelRG_Link">
    <inertial>
      <origin
        xyz="-1.4801E-07 -0.033261 -3.766E-06"
        rpy="0 0 0" />
      <mass
        value="0.83212" />
      <inertia
        ixx="0.0020122"
        ixy="5.9315E-09"
        ixz="6.7329E-13"
        iyy="0.0034308"
        iyz="6.1377E-08"
        izz="0.002012" />
    </inertial>
    <visual>
      <origin
        xyz="0 0 0"
        rpy="0 0 0" />
      <geometry>
        <mesh
          filename="package://grobot/meshes/wheelRG_Link.STL" />
      </geometry>
      <material
        name="">
        <color
          rgba="0.79216 0.81961 0.93333 1" />
      </material>
    </visual>
    <collision>
      <origin
        xyz="0 0 0"
        rpy="0 0 0" />
      <geometry>
        <mesh
          filename="package://grobot/meshes/wheelRG_Link.STL" />
      </geometry>
    </collision>
  </link>
  <joint
    name="wheelRG_joint"
    type="continuous">
    <origin
      xyz="0 0.191 0"
      rpy="0 0 0" />
    <parent
      link="axe2_Link" />
    <child
      link="wheelRG_Link" />
    <axis
      xyz="0 1 0" />
  </joint>
  <link
    name="wheelRAdro_Link">
    <inertial>
      <origin
        xyz="9.8557E-07 0.033261 3.6377E-06"
        rpy="0 0 0" />
      <mass
        value="0.83212" />
      <inertia
        ixx="0.0020121"
        ixy="1.2705E-08"
        ixz="-3.0133E-08"
        iyy="0.0034308"
        iyz="6.034E-08"
        izz="0.0020121" />
    </inertial>
    <visual>
      <origin
        xyz="0 0 0"
        rpy="0 0 0" />
      <geometry>
        <mesh
          filename="package://grobot/meshes/wheelRAdro_Link.STL" />
      </geometry>
      <material
        name="">
        <color
          rgba="0.79216 0.81961 0.93333 1" />
      </material>
    </visual>
    <collision>
      <origin
        xyz="0 0 0"
        rpy="0 0 0" />
      <geometry>
        <mesh
          filename="package://grobot/meshes/wheelRAdro_Link.STL" />
      </geometry>
    </collision>
  </link>
  <joint
    name="wheelRAdroit"
    type="continuous">
    <origin
      xyz="0 -0.191 0"
      rpy="0 0 0" />
    <parent
      link="axe2_Link" />
    <child
      link="wheelRAdro_Link" />
    <axis
      xyz="0 1 0" />
  </joint>
  <link
    name="ax1_Link">
    <inertial>
      <origin
        xyz="1.38777878078145E-17 -6.07153216591882E-17 0"
        rpy="0 0 0" />
      <mass
        value="0.0243473430653209" />
      <inertia
        ixx="0.00019513380994227"
        ixy="-1.33328223455492E-18"
        ixz="-4.82522023984462E-24"
        iyy="3.04341788316511E-07"
        iyz="6.95996023743593E-21"
        izz="0.00019513380994227" />
    </inertial>
    <visual>
      <origin
        xyz="0 0 0"
        rpy="0 0 0" />
      <geometry>
        <mesh
          filename="package://grobot/meshes/ax1_Link.STL" />
      </geometry>
      <material
        name="">
        <color
          rgba="0.792156862745098 0.819607843137255 0.933333333333333 1" />
      </material>
    </visual>
    <collision>
      <origin
        xyz="0 0 0"
        rpy="0 0 0" />
      <geometry>
        <mesh
          filename="package://grobot/meshes/ax1_Link.STL" />
      </geometry>
    </collision>
  </link>
  <joint
    name="axe1_joint"
    type="fixed">
    <origin
      xyz="-0.084417 -0.0090943 -0.043"
      rpy="0 0 0" />
    <parent
      link="base_link" />
    <child
      link="ax1_Link" />
    <axis
      xyz="0 0 0" />
  </joint>
  <link
    name="wheelRD_Link">
    <inertial>
      <origin
        xyz="1.2459E-06 0.033261 3.5569E-06"
        rpy="0 0 0" />
      <mass
        value="0.83212" />
      <inertia
        ixx="0.0020121"
        ixy="1.6988E-08"
        ixz="-3.6065E-08"
        iyy="0.0034308"
        iyz="5.9228E-08"
        izz="0.0020121" />
    </inertial>
    <visual>
      <origin
        xyz="0 0 0"
        rpy="0 0 0" />
      <geometry>
        <mesh
          filename="package://grobot/meshes/wheelRD_Link.STL" />
      </geometry>
      <material
        name="">
        <color
          rgba="0.1098 0.1098 0.1098 1" />
      </material>
    </visual>
    <collision>
      <origin
        xyz="0 0 0"
        rpy="0 0 0" />
      <geometry>
        <mesh
          filename="package://grobot/meshes/wheelRD_Link.STL" />
      </geometry>
    </collision>
  </link>
  <joint
    name="wheelRD"
    type="continuous">
    <origin
      xyz="0 -0.191 0"
      rpy="0 0 0" />
    <parent
      link="ax1_Link" />
    <child
      link="wheelRD_Link" />
    <axis
      xyz="0 1 0" />
  </joint>
  <link
    name="wheelRGD_Link">
    <inertial>
      <origin
        xyz="2.0617E-06 -0.033261 -3.155E-06"
        rpy="0 0 0" />
      <mass
        value="0.83212" />
      <inertia
        ixx="0.0020121"
        ixy="-3.0733E-08"
        ixz="4.9846E-08"
        iyy="0.0034308"
        iyz="5.3459E-08"
        izz="0.0020121" />
    </inertial>
    <visual>
      <origin
        xyz="0 0 0"
        rpy="0 0 0" />
      <geometry>
        <mesh
          filename="package://grobot/meshes/wheelRGD_Link.STL" />
      </geometry>
      <material
        name="">
        <color
          rgba="0.1098 0.1098 0.1098 1" />
      </material>
    </visual>
    <collision>
      <origin
        xyz="0 0 0"
        rpy="0 0 0" />
      <geometry>
        <mesh
          filename="package://grobot/meshes/wheelRGD_Link.STL" />
      </geometry>
    </collision>
  </link>
  <joint
    name="wheelRGD"
    type="continuous">
    <origin
      xyz="0 0.191 0"
      rpy="0 0 0" />
    <parent
      link="ax1_Link" />
    <child
      link="wheelRGD_Link" />
    <axis
      xyz="0 1 0" />
  </joint>
</robot>